<?xml version="1.0"?>
<robot name="red_box_car">

  <!-- Define properties -->
  <xacro:property name="chassis_length" value="0.6" xmlns:xacro="http://www.ros.org/wiki/xacro"/>
  <xacro:property name="chassis_width" value="0.4" xmlns:xacro="http://www.ros.org/wiki/xacro"/>
  <xacro:property name="chassis_height" value="0.15" xmlns:xacro="http://www.ros.org/wiki/xacro"/>
  <xacro:property name="wheel_radius" value="0.1" xmlns:xacro="http://www.ros.org/wiki/xacro"/>
  <xacro:property name="wheel_width" value="0.05" xmlns:xacro="http://www.ros.org/wiki/xacro"/>

  <!-- Materials -->
  <material name="blue">
    <color rgba="0 0 0.8 1"/>
  </material>
  
  <material name="black">
    <color rgba="0 0 0 1"/>
  </material>
  
  <material name="red">
    <color rgba="0.8 0 0 1"/>
  </material>
  
  <material name="gray">
    <color rgba="0.5 0.5 0.5 1"/>
  </material>
  
  <material name="green">
    <color rgba="0 0.8 0 1"/>
  </material>

  <!-- Base link (chassis) -->
  <link name="base_link">
    <visual>
      <origin xyz="0 0 0" rpy="0 0 0"/>
      <geometry>
        <box size="0.6 0.4 0.15"/>
      </geometry>
      <material name="blue"/>
    </visual>
    <collision>
      <origin xyz="0 0 0" rpy="0 0 0"/>
      <geometry>
        <box size="0.6 0.4 0.15"/>
      </geometry>
    </collision>
    <inertial>
      <mass value="10.0"/>
      <origin xyz="0 0 0" rpy="0 0 0"/>
      <inertia ixx="0.4" ixy="0.0" ixz="0.0" iyy="1.0" iyz="0.0" izz="1.2"/>
    </inertial>
  </link>

  <!-- Front left wheel -->
  <link name="front_left_wheel">
    <visual>
      <origin xyz="0 0 0" rpy="1.5708 0 0"/>
      <geometry>
        <cylinder radius="0.1" length="0.05"/>
      </geometry>
      <material name="black"/>
    </visual>
    <collision>
      <origin xyz="0 0 0" rpy="1.5708 0 0"/>
      <geometry>
        <cylinder radius="0.1" length="0.05"/>
      </geometry>
    </collision>
    <inertial>
      <mass value="2.0"/>
      <origin xyz="0 0 0" rpy="1.5708 0 0"/>
      <inertia ixx="0.02" ixy="0.0" ixz="0.0" iyy="0.02" iyz="0.0" izz="0.02"/>
    </inertial>
  </link>

  <!-- Front right wheel -->
  <link name="front_right_wheel">
    <visual>
      <origin xyz="0 0 0" rpy="1.5708 0 0"/>
      <geometry>
        <cylinder radius="0.1" length="0.05"/>
      </geometry>
      <material name="black"/>
    </visual>
    <collision>
      <origin xyz="0 0 0" rpy="1.5708 0 0"/>
      <geometry>
        <cylinder radius="0.1" length="0.05"/>
      </geometry>
    </collision>
    <inertial>
      <mass value="2.0"/>
      <origin xyz="0 0 0" rpy="1.5708 0 0"/>
      <inertia ixx="0.02" ixy="0.0" ixz="0.0" iyy="0.02" iyz="0.0" izz="0.02"/>
    </inertial>
  </link>

  <!-- Rear left wheel -->
  <link name="rear_left_wheel">
    <visual>
      <origin xyz="0 0 0" rpy="1.5708 0 0"/>
      <geometry>
        <cylinder radius="0.1" length="0.05"/>
      </geometry>
      <material name="black"/>
    </visual>
    <collision>
      <origin xyz="0 0 0" rpy="1.5708 0 0"/>
      <geometry>
        <cylinder radius="0.1" length="0.05"/>
      </geometry>
    </collision>
    <inertial>
      <mass value="2.0"/>
      <origin xyz="0 0 0" rpy="1.5708 0 0"/>
      <inertia ixx="0.02" ixy="0.0" ixz="0.0" iyy="0.02" iyz="0.0" izz="0.02"/>
    </inertial>
  </link>

  <!-- Rear right wheel -->
  <link name="rear_right_wheel">
    <visual>
      <origin xyz="0 0 0" rpy="1.5708 0 0"/>
      <geometry>
        <cylinder radius="0.1" length="0.05"/>
      </geometry>
      <material name="black"/>
    </visual>
    <collision>
      <origin xyz="0 0 0" rpy="1.5708 0 0"/>
      <geometry>
        <cylinder radius="0.1" length="0.05"/>
      </geometry>
    </collision>
    <inertial>
      <mass value="2.0"/>
      <origin xyz="0 0 0" rpy="1.5708 0 0"/>
      <inertia ixx="0.02" ixy="0.0" ixz="0.0" iyy="0.02" iyz="0.0" izz="0.02"/>
    </inertial>
  </link>

  <!-- Camera link -->
  <link name="camera_link">
    <visual>
      <origin xyz="0 0 0" rpy="0 0 0"/>
      <geometry>
        <box size="0.05 0.05 0.05"/>
      </geometry>
      <material name="red"/>
    </visual>
    <collision>
      <origin xyz="0 0 0" rpy="0 0 0"/>
      <geometry>
        <box size="0.05 0.05 0.05"/>
      </geometry>
    </collision>
    <inertial>
      <mass value="0.1"/>
      <origin xyz="0 0 0" rpy="0 0 0"/>
      <inertia ixx="0.001" ixy="0.0" ixz="0.0" iyy="0.001" iyz="0.0" izz="0.001"/>
    </inertial>
  </link>

  <!-- Joints -->
  <!-- Wheel joints -->
  <joint name="front_left_wheel_joint" type="continuous">
    <parent link="base_link"/>
    <child link="front_left_wheel"/>
    <origin xyz="0.2 0.25 -0.05" rpy="0 0 0"/>
    <axis xyz="0 1 0"/>
  </joint>

  <joint name="front_right_wheel_joint" type="continuous">
    <parent link="base_link"/>
    <child link="front_right_wheel"/>
    <origin xyz="0.2 -0.25 -0.05" rpy="0 0 0"/>
    <axis xyz="0 1 0"/>
  </joint>

  <joint name="rear_left_wheel_joint" type="continuous">
    <parent link="base_link"/>
    <child link="rear_left_wheel"/>
    <origin xyz="-0.2 0.25 -0.05" rpy="0 0 0"/>
    <axis xyz="0 1 0"/>
  </joint>

  <joint name="rear_right_wheel_joint" type="continuous">
    <parent link="base_link"/>
    <child link="rear_right_wheel"/>
    <origin xyz="-0.2 -0.25 -0.05" rpy="0 0 0"/>
    <axis xyz="0 1 0"/>
  </joint>

  <!-- Camera joint -->
  <joint name="camera_joint" type="fixed">
    <parent link="base_link"/>
    <child link="camera_link"/>
    <origin xyz="0.35 0 0.15" rpy="0 0 0"/>
  </joint>

  <!-- Gazebo materials and physics properties -->
  <gazebo reference="base_link">
    <material>
      <ambient>0 0 0.8 1</ambient>
      <diffuse>0 0 0.8 1</diffuse>
    </material>
    <mu1>0.2</mu1>
    <mu2>0.2</mu2>
  </gazebo>

  <gazebo reference="front_left_wheel">
    <material>
      <ambient>0.2 0.2 0.2 1</ambient>
      <diffuse>0.2 0.2 0.2 1</diffuse>
    </material>
    <mu1>1.0</mu1>
    <mu2>1.0</mu2>
  </gazebo>

  <gazebo reference="front_right_wheel">
    <material>
      <ambient>0.2 0.2 0.2 1</ambient>
      <diffuse>0.2 0.2 0.2 1</diffuse>
    </material>
    <mu1>1.0</mu1>
    <mu2>1.0</mu2>
  </gazebo>

  <gazebo reference="rear_left_wheel">
    <material>
      <ambient>0.2 0.2 0.2 1</ambient>
      <diffuse>0.2 0.2 0.2 1</diffuse>
    </material>
    <mu1>1.0</mu1>
    <mu2>1.0</mu2>
  </gazebo>

  <gazebo reference="rear_right_wheel">
    <material>
      <ambient>0.2 0.2 0.2 1</ambient>
      <diffuse>0.2 0.2 0.2 1</diffuse>
    </material>
    <mu1>1.0</mu1>
    <mu2>1.0</mu2>
  </gazebo>

  <gazebo reference="camera_link">
    <material>
      <ambient>0.8 0 0 1</ambient>
      <diffuse>0.8 0 0 1</diffuse>
    </material>
  </gazebo>

  <!-- Differential Drive Plugin for Gazebo Garden/Harmonic -->
  <gazebo>
    <plugin filename="gz-sim-diff-drive-system" name="gz::sim::systems::DiffDrive">
      <!-- Wheel Information -->
      <left_joint>rear_left_wheel_joint</left_joint>
      <right_joint>rear_right_wheel_joint</right_joint>
      <wheel_separation>0.4</wheel_separation>
      <wheel_radius>0.1</wheel_radius>
      
      <!-- Limits -->
      <max_linear_velocity>2.0</max_linear_velocity>
      <min_linear_velocity>-2.0</min_linear_velocity>
      <max_angular_velocity>1.0</max_angular_velocity>
      <min_angular_velocity>-1.0</min_angular_velocity>
      
      <!-- Topic names -->
      <topic>cmd_vel</topic>
      <odom_topic>odom</odom_topic>
      <frame_id>odom</frame_id>
      <child_frame_id>base_link</child_frame_id>
      
      <!-- Publishing options -->
      <odom_publish_frequency>50</odom_publish_frequency>
    </plugin>
  </gazebo>

</robot>